ERROR:__mp_main__.lightning_board_BTC_JPY:[WinError 10060] 接続済みの呼び出し先が一定の時間を過ぎても正しく応答しなかったため、接続できませんでした。または接続済みのホストが応答しなかったため、確立された接続は失敗しました。
Traceback (most recent call last):
  File "C:\Users\hks-s\Anaconda3\lib\site-packages\websocket\_app.py", line 292, in run_forever
    self.sock.connect(
  File "C:\Users\hks-s\Anaconda3\lib\site-packages\websocket\_core.py", line 248, in connect
    self.sock, addrs = connect(url, self.sock_opt, proxy_info(**options),
  File "C:\Users\hks-s\Anaconda3\lib\site-packages\websocket\_http.py", line 120, in connect
    sock = _open_socket(addrinfo_list, options.sockopt, options.timeout)
  File "C:\Users\hks-s\Anaconda3\lib\site-packages\websocket\_http.py", line 192, in _open_socket
    raise error
  File "C:\Users\hks-s\Anaconda3\lib\site-packages\websocket\_http.py", line 175, in _open_socket
    sock.connect(address)
TimeoutError: [WinError 10060] 接続済みの呼び出し先が一定の時間を過ぎても正しく応答しなかったため、接続できませんでした。または接続済みのホストが応答しなかったため、確立された接続は失敗しました。
WARNING:__mp_main__.lightning_board_BTC_JPY:closed
ERROR:__mp_main__.lightning_board_BTC_JPY:[WinError 10060] 接続済みの呼び出し先が一定の時間を過ぎても正しく応答しなかったため、接続できませんでした。または接続済みのホストが応答しなかったため、確立された接続は失敗しました。
Traceback (most recent call last):
  File "C:\Users\hks-s\Anaconda3\lib\site-packages\websocket\_app.py", line 292, in run_forever
    self.sock.connect(
  File "C:\Users\hks-s\Anaconda3\lib\site-packages\websocket\_core.py", line 248, in connect
    self.sock, addrs = connect(url, self.sock_opt, proxy_info(**options),
  File "C:\Users\hks-s\Anaconda3\lib\site-packages\websocket\_http.py", line 120, in connect
    sock = _open_socket(addrinfo_list, options.sockopt, options.timeout)
  File "C:\Users\hks-s\Anaconda3\lib\site-packages\websocket\_http.py", line 192, in _open_socket
    raise error
  File "C:\Users\hks-s\Anaconda3\lib\site-packages\websocket\_http.py", line 175, in _open_socket
    sock.connect(address)
TimeoutError: [WinError 10060] 接続済みの呼び出し先が一定の時間を過ぎても正しく応答しなかったため、接続できませんでした。または接続済みのホストが応答しなかったため、確立された接続は失敗しました。
WARNING:__mp_main__.lightning_board_BTC_JPY:closed
ERROR:__mp_main__.lightning_board_BTC_JPY:[WinError 10060] 接続済みの呼び出し先が一定の時間を過ぎても正しく応答しなかったため、接続できませんでした。または接続済みのホストが応答しなかったため、確立された接続は失敗しました。
Traceback (most recent call last):
  File "C:\Users\hks-s\Anaconda3\lib\site-packages\websocket\_app.py", line 292, in run_forever
    self.sock.connect(
  File "C:\Users\hks-s\Anaconda3\lib\site-packages\websocket\_core.py", line 248, in connect
    self.sock, addrs = connect(url, self.sock_opt, proxy_info(**options),
  File "C:\Users\hks-s\Anaconda3\lib\site-packages\websocket\_http.py", line 120, in connect
    sock = _open_socket(addrinfo_list, options.sockopt, options.timeout)
  File "C:\Users\hks-s\Anaconda3\lib\site-packages\websocket\_http.py", line 192, in _open_socket
    raise error
  File "C:\Users\hks-s\Anaconda3\lib\site-packages\websocket\_http.py", line 175, in _open_socket
    sock.connect(address)
TimeoutError: [WinError 10060] 接続済みの呼び出し先が一定の時間を過ぎても正しく応答しなかったため、接続できませんでした。または接続済みのホストが応答しなかったため、確立された接続は失敗しました。
WARNING:__mp_main__.lightning_board_BTC_JPY:closed
ERROR:__mp_main__.lightning_board_BTC_JPY:[WinError 10060] 接続済みの呼び出し先が一定の時間を過ぎても正しく応答しなかったため、接続できませんでした。または接続済みのホストが応答しなかったため、確立された接続は失敗しました。
Traceback (most recent call last):
  File "C:\Users\hks-s\Anaconda3\lib\site-packages\websocket\_app.py", line 292, in run_forever
    self.sock.connect(
  File "C:\Users\hks-s\Anaconda3\lib\site-packages\websocket\_core.py", line 248, in connect
    self.sock, addrs = connect(url, self.sock_opt, proxy_info(**options),
  File "C:\Users\hks-s\Anaconda3\lib\site-packages\websocket\_http.py", line 120, in connect
    sock = _open_socket(addrinfo_list, options.sockopt, options.timeout)
  File "C:\Users\hks-s\Anaconda3\lib\site-packages\websocket\_http.py", line 192, in _open_socket
    raise error
  File "C:\Users\hks-s\Anaconda3\lib\site-packages\websocket\_http.py", line 175, in _open_socket
    sock.connect(address)
TimeoutError: [WinError 10060] 接続済みの呼び出し先が一定の時間を過ぎても正しく応答しなかったため、接続できませんでした。または接続済みのホストが応答しなかったため、確立された接続は失敗しました。
WARNING:__mp_main__.lightning_board_BTC_JPY:closed
ERROR:__mp_main__.lightning_board_BTC_JPY:[WinError 10060] 接続済みの呼び出し先が一定の時間を過ぎても正しく応答しなかったため、接続できませんでした。または接続済みのホストが応答しなかったため、確立された接続は失敗しました。
Traceback (most recent call last):
  File "C:\Users\hks-s\Anaconda3\lib\site-packages\websocket\_app.py", line 292, in run_forever
    self.sock.connect(
  File "C:\Users\hks-s\Anaconda3\lib\site-packages\websocket\_core.py", line 248, in connect
    self.sock, addrs = connect(url, self.sock_opt, proxy_info(**options),
  File "C:\Users\hks-s\Anaconda3\lib\site-packages\websocket\_http.py", line 120, in connect
    sock = _open_socket(addrinfo_list, options.sockopt, options.timeout)
  File "C:\Users\hks-s\Anaconda3\lib\site-packages\websocket\_http.py", line 192, in _open_socket
    raise error
  File "C:\Users\hks-s\Anaconda3\lib\site-packages\websocket\_http.py", line 175, in _open_socket
    sock.connect(address)
TimeoutError: [WinError 10060] 接続済みの呼び出し先が一定の時間を過ぎても正しく応答しなかったため、接続できませんでした。または接続済みのホストが応答しなかったため、確立された接続は失敗しました。
WARNING:__mp_main__.lightning_board_BTC_JPY:closed
ERROR:__mp_main__.lightning_board_BTC_JPY:[WinError 10060] 接続済みの呼び出し先が一定の時間を過ぎても正しく応答しなかったため、接続できませんでした。または接続済みのホストが応答しなかったため、確立された接続は失敗しました。
Traceback (most recent call last):
  File "C:\Users\hks-s\Anaconda3\lib\site-packages\websocket\_app.py", line 292, in run_forever
    self.sock.connect(
  File "C:\Users\hks-s\Anaconda3\lib\site-packages\websocket\_core.py", line 248, in connect
    self.sock, addrs = connect(url, self.sock_opt, proxy_info(**options),
  File "C:\Users\hks-s\Anaconda3\lib\site-packages\websocket\_http.py", line 120, in connect
    sock = _open_socket(addrinfo_list, options.sockopt, options.timeout)
  File "C:\Users\hks-s\Anaconda3\lib\site-packages\websocket\_http.py", line 192, in _open_socket
    raise error
  File "C:\Users\hks-s\Anaconda3\lib\site-packages\websocket\_http.py", line 175, in _open_socket
    sock.connect(address)
TimeoutError: [WinError 10060] 接続済みの呼び出し先が一定の時間を過ぎても正しく応答しなかったため、接続できませんでした。または接続済みのホストが応答しなかったため、確立された接続は失敗しました。
WARNING:__mp_main__.lightning_board_BTC_JPY:closed
ERROR:__mp_main__.lightning_board_BTC_JPY:[WinError 10060] 接続済みの呼び出し先が一定の時間を過ぎても正しく応答しなかったため、接続できませんでした。または接続済みのホストが応答しなかったため、確立された接続は失敗しました。
Traceback (most recent call last):
  File "C:\Users\hks-s\Anaconda3\lib\site-packages\websocket\_app.py", line 292, in run_forever
    self.sock.connect(
  File "C:\Users\hks-s\Anaconda3\lib\site-packages\websocket\_core.py", line 248, in connect
    self.sock, addrs = connect(url, self.sock_opt, proxy_info(**options),
  File "C:\Users\hks-s\Anaconda3\lib\site-packages\websocket\_http.py", line 120, in connect
    sock = _open_socket(addrinfo_list, options.sockopt, options.timeout)
  File "C:\Users\hks-s\Anaconda3\lib\site-packages\websocket\_http.py", line 192, in _open_socket
    raise error
  File "C:\Users\hks-s\Anaconda3\lib\site-packages\websocket\_http.py", line 175, in _open_socket
    sock.connect(address)
TimeoutError: [WinError 10060] 接続済みの呼び出し先が一定の時間を過ぎても正しく応答しなかったため、接続できませんでした。または接続済みのホストが応答しなかったため、確立された接続は失敗しました。
WARNING:__mp_main__.lightning_board_BTC_JPY:closed
ERROR:__mp_main__.lightning_board_BTC_JPY:[WinError 10060] 接続済みの呼び出し先が一定の時間を過ぎても正しく応答しなかったため、接続できませんでした。または接続済みのホストが応答しなかったため、確立された接続は失敗しました。
Traceback (most recent call last):
  File "C:\Users\hks-s\Anaconda3\lib\site-packages\websocket\_app.py", line 292, in run_forever
    self.sock.connect(
  File "C:\Users\hks-s\Anaconda3\lib\site-packages\websocket\_core.py", line 248, in connect
    self.sock, addrs = connect(url, self.sock_opt, proxy_info(**options),
  File "C:\Users\hks-s\Anaconda3\lib\site-packages\websocket\_http.py", line 120, in connect
    sock = _open_socket(addrinfo_list, options.sockopt, options.timeout)
  File "C:\Users\hks-s\Anaconda3\lib\site-packages\websocket\_http.py", line 192, in _open_socket
    raise error
  File "C:\Users\hks-s\Anaconda3\lib\site-packages\websocket\_http.py", line 175, in _open_socket
    sock.connect(address)
TimeoutError: [WinError 10060] 接続済みの呼び出し先が一定の時間を過ぎても正しく応答しなかったため、接続できませんでした。または接続済みのホストが応答しなかったため、確立された接続は失敗しました。
WARNING:__mp_main__.lightning_board_BTC_JPY:closed
ERROR:__mp_main__.lightning_board_BTC_JPY:[WinError 10060] 接続済みの呼び出し先が一定の時間を過ぎても正しく応答しなかったため、接続できませんでした。または接続済みのホストが応答しなかったため、確立された接続は失敗しました。
Traceback (most recent call last):
  File "C:\Users\hks-s\Anaconda3\lib\site-packages\websocket\_app.py", line 292, in run_forever
    self.sock.connect(
  File "C:\Users\hks-s\Anaconda3\lib\site-packages\websocket\_core.py", line 248, in connect
    self.sock, addrs = connect(url, self.sock_opt, proxy_info(**options),
  File "C:\Users\hks-s\Anaconda3\lib\site-packages\websocket\_http.py", line 120, in connect
    sock = _open_socket(addrinfo_list, options.sockopt, options.timeout)
  File "C:\Users\hks-s\Anaconda3\lib\site-packages\websocket\_http.py", line 192, in _open_socket
    raise error
  File "C:\Users\hks-s\Anaconda3\lib\site-packages\websocket\_http.py", line 175, in _open_socket
    sock.connect(address)
TimeoutError: [WinError 10060] 接続済みの呼び出し先が一定の時間を過ぎても正しく応答しなかったため、接続できませんでした。または接続済みのホストが応答しなかったため、確立された接続は失敗しました。
WARNING:__mp_main__.lightning_board_BTC_JPY:closed
ERROR:__mp_main__.lightning_board_BTC_JPY:[WinError 10060] 接続済みの呼び出し先が一定の時間を過ぎても正しく応答しなかったため、接続できませんでした。または接続済みのホストが応答しなかったため、確立された接続は失敗しました。
Traceback (most recent call last):
  File "C:\Users\hks-s\Anaconda3\lib\site-packages\websocket\_app.py", line 292, in run_forever
    self.sock.connect(
  File "C:\Users\hks-s\Anaconda3\lib\site-packages\websocket\_core.py", line 248, in connect
    self.sock, addrs = connect(url, self.sock_opt, proxy_info(**options),
  File "C:\Users\hks-s\Anaconda3\lib\site-packages\websocket\_http.py", line 120, in connect
    sock = _open_socket(addrinfo_list, options.sockopt, options.timeout)
  File "C:\Users\hks-s\Anaconda3\lib\site-packages\websocket\_http.py", line 192, in _open_socket
    raise error
  File "C:\Users\hks-s\Anaconda3\lib\site-packages\websocket\_http.py", line 175, in _open_socket
    sock.connect(address)
TimeoutError: [WinError 10060] 接続済みの呼び出し先が一定の時間を過ぎても正しく応答しなかったため、接続できませんでした。または接続済みのホストが応答しなかったため、確立された接続は失敗しました。
WARNING:__mp_main__.lightning_board_BTC_JPY:closed
